{"uuid": "af5b235d-a4d2-4c9c-bc99-6dc3b5507889", "children": ["578625f6-9536-4d0a-8418-27969e0ca225"], "befores": [{"name": "driver", "status": "broken", "statusDetails": {"message": "selenium.common.exceptions.WebDriverException: Message: An unknown server-side error occurred while processing the command. Original error: Could not find a connected Android device in 20000ms\nStacktrace:\nUnknownError: An unknown server-side error occurred while processing the command. Original error: Could not find a connected Android device in 20000ms\n    at getResponseForW3CError (C:\\Users\\HP\\AppData\\Roaming\\npm\\node_modules\\appium\\node_modules\\@appium\\base-driver\\lib\\protocol\\errors.js:1143:9)\n    at asyncHandler (C:\\Users\\HP\\AppData\\Roaming\\npm\\node_modules\\appium\\node_modules\\@appium\\base-driver\\lib\\protocol\\protocol.js:487:57)\n", "trace": "  File \"C:\\Users\\HP\\appium_env\\Lib\\site-packages\\pluggy\\_callers.py\", line 38, in run_old_style_hookwrapper\n    res = yield\n          ^^^^^\n  File \"C:\\Users\\HP\\appium_env\\Lib\\site-packages\\pluggy\\_callers.py\", line 139, in _multicall\n    teardown.throw(exception)\n  File \"C:\\Users\\HP\\appium_env\\Lib\\site-packages\\_pytest\\setuponly.py\", line 36, in pytest_fixture_setup\n    return (yield)\n            ^^^^^\n  File \"C:\\Users\\HP\\appium_env\\Lib\\site-packages\\pluggy\\_callers.py\", line 121, in _multicall\n    res = hook_impl.function(*args)\n          ^^^^^^^^^^^^^^^^^^^^^^^^^\n  File \"C:\\Users\\HP\\appium_env\\Lib\\site-packages\\_pytest\\fixtures.py\", line 1195, in pytest_fixture_setup\n    result = call_fixture_func(fixturefunc, request, kwargs)\n             ^^^^^^^^^^^^^^^^^^^^^^^^^^^^^^^^^^^^^^^^^^^^^^^\n  File \"C:\\Users\\HP\\appium_env\\Lib\\site-packages\\_pytest\\fixtures.py\", line 922, in call_fixture_func\n    fixture_result = next(generator)\n                     ^^^^^^^^^^^^^^^\n  File \"C:\\Users\\HP\\PycharmProjects\\appiumTestProject\\tests\\test_calc.py\", line 20, in driver\n    driver = webdriver.Remote(\"http://127.0.0.1:4723\", options=options)\n             ^^^^^^^^^^^^^^^^^^^^^^^^^^^^^^^^^^^^^^^^^^^^^^^^^^^^^^^^^^\n  File \"C:\\Users\\HP\\appium_env\\Lib\\site-packages\\appium\\webdriver\\webdriver.py\", line 238, in __init__\n    super().__init__(\n  File \"C:\\Users\\HP\\appium_env\\Lib\\site-packages\\selenium\\webdriver\\remote\\webdriver.py\", line 257, in __init__\n    self.start_session(capabilities)\n  File \"C:\\Users\\HP\\appium_env\\Lib\\site-packages\\appium\\webdriver\\webdriver.py\", line 329, in start_session\n    response = self.execute(RemoteCommand.NEW_SESSION, w3c_caps)\n               ^^^^^^^^^^^^^^^^^^^^^^^^^^^^^^^^^^^^^^^^^^^^^^^^^\n  File \"C:\\Users\\HP\\appium_env\\Lib\\site-packages\\selenium\\webdriver\\remote\\webdriver.py\", line 447, in execute\n    self.error_handler.check_response(response)\n  File \"C:\\Users\\HP\\appium_env\\Lib\\site-packages\\selenium\\webdriver\\remote\\errorhandler.py\", line 232, in check_response\n    raise exception_class(message, screen, stacktrace)\n"}, "start": 1750145470332, "stop": 1750145490600}], "start": 1750145470332, "stop": 1750145491029}